2020-12-22 18:12:32 Config:
{'all_joints': [[0],
                [1],
                [2],
                [3],
                [4],
                [5],
                [6],
                [7],
                [8],
                [9],
                [10],
                [11],
                [12],
                [13],
                [14],
                [15],
                [16],
                [17],
                [18],
                [19],
                [20]],
 'batch_size': 1,
 'crop': False,
 'crop_pad': 0,
 'dataset': './dataset/np_struct_arr.mat',
 'dataset_type': 'mpii',
 'display_iters': 50,
 'fg_fraction': 0.25,
 'global_scale': 1,
 'init_weights': './pretrained/resnet_v1_50.ckpt',
 'intermediate_supervision': False,
 'intermediate_supervision_layer': 12,
 'location_refinement': True,
 'locref_huber_loss': True,
 'locref_loss_weight': 0.05,
 'locref_stdev': 7.2801,
 'log_dir': 'log',
 'max_input_size': 850,
 'mean_pixel': [123.68, 116.779, 103.939],
 'mirror': False,
 'multi_step': [[0.005, 10000],
                [0.02, 430000],
                [0.002, 730000],
                [0.001, 1030000]],
 'net_type': 'resnet_50',
 'optimizer': 'sgd',
 'pairwise_huber_loss': True,
 'pairwise_loss_weight': 1.0,
 'pairwise_predict': False,
 'pairwise_stats_collect': False,
 'pairwise_stats_fn': 'pairwise_stats.mat',
 'pos_dist_thresh': 17,
 'regularize': False,
 'save_iters': 5,
 'scale_jitter_lo': 1,
 'scale_jitter_up': 1,
 'scoremap_dir': 'test',
 'shuffle': True,
 'snapshot_prefix': 'snapshot',
 'sparse_graph': [],
 'stride': 8.0,
 'tensorflow_pairwise_order': True,
 'use_gt_segm': False,
 'video': False,
 'video_batch': False,
 'weigh_negatives': False,
 'weigh_only_present_joints': False,
 'weigh_part_predictions': False,
 'weight_decay': 0.0001}
2020-12-22 18:12:32 From train.py:37: The name tf.placeholder is deprecated. Please use tf.compat.v1.placeholder instead.

2020-12-22 18:12:32 From train.py:42: The name tf.FIFOQueue is deprecated. Please use tf.queue.FIFOQueue instead.

2020-12-22 18:12:32 Entity <bound method Conv.call of <tensorflow.python.layers.convolutional.Conv2D object at 0x00000262155C5780>> could not be transformed and will be executed as-is. Please report this to the AutgoGraph team. When filing the bug, set the verbosity to 10 (on Linux, `export AUTOGRAPH_VERBOSITY=10`) and attach the full output. Cause: converting <bound method Conv.call of <tensorflow.python.layers.convolutional.Conv2D object at 0x00000262155C5780>>: AssertionError: Bad argument number for Name: 3, expecting 4
2020-12-22 18:12:32 Entity <bound method BatchNormalization.call of <tensorflow.python.layers.normalization.BatchNormalization object at 0x000002621566B278>> could not be transformed and will be executed as-is. Please report this to the AutgoGraph team. When filing the bug, set the verbosity to 10 (on Linux, `export AUTOGRAPH_VERBOSITY=10`) and attach the full output. Cause: converting <bound method BatchNormalization.call of <tensorflow.python.layers.normalization.BatchNormalization object at 0x000002621566B278>>: AssertionError: Bad argument number for Name: 3, expecting 4
2020-12-22 18:12:32 Entity <bound method Pooling2D.call of <tensorflow.python.layers.pooling.MaxPooling2D object at 0x00000262155C5940>> could not be transformed and will be executed as-is. Please report this to the AutgoGraph team. When filing the bug, set the verbosity to 10 (on Linux, `export AUTOGRAPH_VERBOSITY=10`) and attach the full output. Cause: converting <bound method Pooling2D.call of <tensorflow.python.layers.pooling.MaxPooling2D object at 0x00000262155C5940>>: AssertionError: Bad argument number for Name: 3, expecting 4
2020-12-22 18:12:32 Entity <bound method Conv.call of <tensorflow.python.layers.convolutional.Conv2D object at 0x00000262156941D0>> could not be transformed and will be executed as-is. Please report this to the AutgoGraph team. When filing the bug, set the verbosity to 10 (on Linux, `export AUTOGRAPH_VERBOSITY=10`) and attach the full output. Cause: converting <bound method Conv.call of <tensorflow.python.layers.convolutional.Conv2D object at 0x00000262156941D0>>: AssertionError: Bad argument number for Name: 3, expecting 4
2020-12-22 18:12:32 Entity <bound method BatchNormalization.call of <tensorflow.python.layers.normalization.BatchNormalization object at 0x00000262155EF5F8>> could not be transformed and will be executed as-is. Please report this to the AutgoGraph team. When filing the bug, set the verbosity to 10 (on Linux, `export AUTOGRAPH_VERBOSITY=10`) and attach the full output. Cause: converting <bound method BatchNormalization.call of <tensorflow.python.layers.normalization.BatchNormalization object at 0x00000262155EF5F8>>: AssertionError: Bad argument number for Name: 3, expecting 4
2020-12-22 18:12:33 Entity <bound method Conv.call of <tensorflow.python.layers.convolutional.Conv2D object at 0x0000026215694978>> could not be transformed and will be executed as-is. Please report this to the AutgoGraph team. When filing the bug, set the verbosity to 10 (on Linux, `export AUTOGRAPH_VERBOSITY=10`) and attach the full output. Cause: converting <bound method Conv.call of <tensorflow.python.layers.convolutional.Conv2D object at 0x0000026215694978>>: AssertionError: Bad argument number for Name: 3, expecting 4
2020-12-22 18:12:33 Entity <bound method BatchNormalization.call of <tensorflow.python.layers.normalization.BatchNormalization object at 0x0000026215696F60>> could not be transformed and will be executed as-is. Please report this to the AutgoGraph team. When filing the bug, set the verbosity to 10 (on Linux, `export AUTOGRAPH_VERBOSITY=10`) and attach the full output. Cause: converting <bound method BatchNormalization.call of <tensorflow.python.layers.normalization.BatchNormalization object at 0x0000026215696F60>>: AssertionError: Bad argument number for Name: 3, expecting 4
2020-12-22 18:12:33 Entity <bound method Conv.call of <tensorflow.python.layers.convolutional.Conv2D object at 0x0000026215694CC0>> could not be transformed and will be executed as-is. Please report this to the AutgoGraph team. When filing the bug, set the verbosity to 10 (on Linux, `export AUTOGRAPH_VERBOSITY=10`) and attach the full output. Cause: converting <bound method Conv.call of <tensorflow.python.layers.convolutional.Conv2D object at 0x0000026215694CC0>>: AssertionError: Bad argument number for Name: 3, expecting 4
2020-12-22 18:12:33 Entity <bound method BatchNormalization.call of <tensorflow.python.layers.normalization.BatchNormalization object at 0x00000262156688D0>> could not be transformed and will be executed as-is. Please report this to the AutgoGraph team. When filing the bug, set the verbosity to 10 (on Linux, `export AUTOGRAPH_VERBOSITY=10`) and attach the full output. Cause: converting <bound method BatchNormalization.call of <tensorflow.python.layers.normalization.BatchNormalization object at 0x00000262156688D0>>: AssertionError: Bad argument number for Name: 3, expecting 4
2020-12-22 18:12:33 Entity <bound method Conv.call of <tensorflow.python.layers.convolutional.Conv2D object at 0x0000026215694A20>> could not be transformed and will be executed as-is. Please report this to the AutgoGraph team. When filing the bug, set the verbosity to 10 (on Linux, `export AUTOGRAPH_VERBOSITY=10`) and attach the full output. Cause: converting <bound method Conv.call of <tensorflow.python.layers.convolutional.Conv2D object at 0x0000026215694A20>>: AssertionError: Bad argument number for Name: 3, expecting 4
2020-12-22 18:12:33 Entity <bound method BatchNormalization.call of <tensorflow.python.layers.normalization.BatchNormalization object at 0x00000262156E25C0>> could not be transformed and will be executed as-is. Please report this to the AutgoGraph team. When filing the bug, set the verbosity to 10 (on Linux, `export AUTOGRAPH_VERBOSITY=10`) and attach the full output. Cause: converting <bound method BatchNormalization.call of <tensorflow.python.layers.normalization.BatchNormalization object at 0x00000262156E25C0>>: AssertionError: Bad argument number for Name: 3, expecting 4
2020-12-22 18:12:33 Entity <bound method Conv.call of <tensorflow.python.layers.convolutional.Conv2D object at 0x0000026215696668>> could not be transformed and will be executed as-is. Please report this to the AutgoGraph team. When filing the bug, set the verbosity to 10 (on Linux, `export AUTOGRAPH_VERBOSITY=10`) and attach the full output. Cause: converting <bound method Conv.call of <tensorflow.python.layers.convolutional.Conv2D object at 0x0000026215696668>>: AssertionError: Bad argument number for Name: 3, expecting 4
2020-12-22 18:12:33 Entity <bound method BatchNormalization.call of <tensorflow.python.layers.normalization.BatchNormalization object at 0x0000026215668D68>> could not be transformed and will be executed as-is. Please report this to the AutgoGraph team. When filing the bug, set the verbosity to 10 (on Linux, `export AUTOGRAPH_VERBOSITY=10`) and attach the full output. Cause: converting <bound method BatchNormalization.call of <tensorflow.python.layers.normalization.BatchNormalization object at 0x0000026215668D68>>: AssertionError: Bad argument number for Name: 3, expecting 4
2020-12-22 18:12:33 Entity <bound method Conv.call of <tensorflow.python.layers.convolutional.Conv2D object at 0x0000026215739B38>> could not be transformed and will be executed as-is. Please report this to the AutgoGraph team. When filing the bug, set the verbosity to 10 (on Linux, `export AUTOGRAPH_VERBOSITY=10`) and attach the full output. Cause: converting <bound method Conv.call of <tensorflow.python.layers.convolutional.Conv2D object at 0x0000026215739B38>>: AssertionError: Bad argument number for Name: 3, expecting 4
2020-12-22 18:12:33 Entity <bound method BatchNormalization.call of <tensorflow.python.layers.normalization.BatchNormalization object at 0x0000026215668D68>> could not be transformed and will be executed as-is. Please report this to the AutgoGraph team. When filing the bug, set the verbosity to 10 (on Linux, `export AUTOGRAPH_VERBOSITY=10`) and attach the full output. Cause: converting <bound method BatchNormalization.call of <tensorflow.python.layers.normalization.BatchNormalization object at 0x0000026215668D68>>: AssertionError: Bad argument number for Name: 3, expecting 4
2020-12-22 18:12:33 Entity <bound method Conv.call of <tensorflow.python.layers.convolutional.Conv2D object at 0x0000026215694668>> could not be transformed and will be executed as-is. Please report this to the AutgoGraph team. When filing the bug, set the verbosity to 10 (on Linux, `export AUTOGRAPH_VERBOSITY=10`) and attach the full output. Cause: converting <bound method Conv.call of <tensorflow.python.layers.convolutional.Conv2D object at 0x0000026215694668>>: AssertionError: Bad argument number for Name: 3, expecting 4
2020-12-22 18:12:33 Entity <bound method BatchNormalization.call of <tensorflow.python.layers.normalization.BatchNormalization object at 0x0000026215778048>> could not be transformed and will be executed as-is. Please report this to the AutgoGraph team. When filing the bug, set the verbosity to 10 (on Linux, `export AUTOGRAPH_VERBOSITY=10`) and attach the full output. Cause: converting <bound method BatchNormalization.call of <tensorflow.python.layers.normalization.BatchNormalization object at 0x0000026215778048>>: AssertionError: Bad argument number for Name: 3, expecting 4
2020-12-22 18:12:34 Entity <bound method Pooling2D.call of <tensorflow.python.layers.pooling.MaxPooling2D object at 0x0000026215798D30>> could not be transformed and will be executed as-is. Please report this to the AutgoGraph team. When filing the bug, set the verbosity to 10 (on Linux, `export AUTOGRAPH_VERBOSITY=10`) and attach the full output. Cause: converting <bound method Pooling2D.call of <tensorflow.python.layers.pooling.MaxPooling2D object at 0x0000026215798D30>>: AssertionError: Bad argument number for Name: 3, expecting 4
2020-12-22 18:12:34 Entity <bound method Conv.call of <tensorflow.python.layers.convolutional.Conv2D object at 0x0000026215798CF8>> could not be transformed and will be executed as-is. Please report this to the AutgoGraph team. When filing the bug, set the verbosity to 10 (on Linux, `export AUTOGRAPH_VERBOSITY=10`) and attach the full output. Cause: converting <bound method Conv.call of <tensorflow.python.layers.convolutional.Conv2D object at 0x0000026215798CF8>>: AssertionError: Bad argument number for Name: 3, expecting 4
2020-12-22 18:12:34 Entity <bound method BatchNormalization.call of <tensorflow.python.layers.normalization.BatchNormalization object at 0x00000262155DE9B0>> could not be transformed and will be executed as-is. Please report this to the AutgoGraph team. When filing the bug, set the verbosity to 10 (on Linux, `export AUTOGRAPH_VERBOSITY=10`) and attach the full output. Cause: converting <bound method BatchNormalization.call of <tensorflow.python.layers.normalization.BatchNormalization object at 0x00000262155DE9B0>>: AssertionError: Bad argument number for Name: 3, expecting 4
2020-12-22 18:12:34 Entity <bound method Conv.call of <tensorflow.python.layers.convolutional.Conv2D object at 0x00000262155DE3C8>> could not be transformed and will be executed as-is. Please report this to the AutgoGraph team. When filing the bug, set the verbosity to 10 (on Linux, `export AUTOGRAPH_VERBOSITY=10`) and attach the full output. Cause: converting <bound method Conv.call of <tensorflow.python.layers.convolutional.Conv2D object at 0x00000262155DE3C8>>: AssertionError: Bad argument number for Name: 3, expecting 4
2020-12-22 18:12:34 Entity <bound method BatchNormalization.call of <tensorflow.python.layers.normalization.BatchNormalization object at 0x00000262156E2518>> could not be transformed and will be executed as-is. Please report this to the AutgoGraph team. When filing the bug, set the verbosity to 10 (on Linux, `export AUTOGRAPH_VERBOSITY=10`) and attach the full output. Cause: converting <bound method BatchNormalization.call of <tensorflow.python.layers.normalization.BatchNormalization object at 0x00000262156E2518>>: AssertionError: Bad argument number for Name: 3, expecting 4
2020-12-22 18:12:34 Entity <bound method Conv.call of <tensorflow.python.layers.convolutional.Conv2D object at 0x00000262158992E8>> could not be transformed and will be executed as-is. Please report this to the AutgoGraph team. When filing the bug, set the verbosity to 10 (on Linux, `export AUTOGRAPH_VERBOSITY=10`) and attach the full output. Cause: converting <bound method Conv.call of <tensorflow.python.layers.convolutional.Conv2D object at 0x00000262158992E8>>: AssertionError: Bad argument number for Name: 3, expecting 4
2020-12-22 18:12:34 Entity <bound method BatchNormalization.call of <tensorflow.python.layers.normalization.BatchNormalization object at 0x0000026215915C18>> could not be transformed and will be executed as-is. Please report this to the AutgoGraph team. When filing the bug, set the verbosity to 10 (on Linux, `export AUTOGRAPH_VERBOSITY=10`) and attach the full output. Cause: converting <bound method BatchNormalization.call of <tensorflow.python.layers.normalization.BatchNormalization object at 0x0000026215915C18>>: AssertionError: Bad argument number for Name: 3, expecting 4
2020-12-22 18:12:34 Entity <bound method Conv.call of <tensorflow.python.layers.convolutional.Conv2D object at 0x00000262155DE3C8>> could not be transformed and will be executed as-is. Please report this to the AutgoGraph team. When filing the bug, set the verbosity to 10 (on Linux, `export AUTOGRAPH_VERBOSITY=10`) and attach the full output. Cause: converting <bound method Conv.call of <tensorflow.python.layers.convolutional.Conv2D object at 0x00000262155DE3C8>>: AssertionError: Bad argument number for Name: 3, expecting 4
2020-12-22 18:12:34 Entity <bound method BatchNormalization.call of <tensorflow.python.layers.normalization.BatchNormalization object at 0x00000262156E2550>> could not be transformed and will be executed as-is. Please report this to the AutgoGraph team. When filing the bug, set the verbosity to 10 (on Linux, `export AUTOGRAPH_VERBOSITY=10`) and attach the full output. Cause: converting <bound method BatchNormalization.call of <tensorflow.python.layers.normalization.BatchNormalization object at 0x00000262156E2550>>: AssertionError: Bad argument number for Name: 3, expecting 4
2020-12-22 18:12:34 Entity <bound method Conv.call of <tensorflow.python.layers.convolutional.Conv2D object at 0x00000262159407B8>> could not be transformed and will be executed as-is. Please report this to the AutgoGraph team. When filing the bug, set the verbosity to 10 (on Linux, `export AUTOGRAPH_VERBOSITY=10`) and attach the full output. Cause: converting <bound method Conv.call of <tensorflow.python.layers.convolutional.Conv2D object at 0x00000262159407B8>>: AssertionError: Bad argument number for Name: 3, expecting 4
2020-12-22 18:12:34 Entity <bound method BatchNormalization.call of <tensorflow.python.layers.normalization.BatchNormalization object at 0x00000262158996A0>> could not be transformed and will be executed as-is. Please report this to the AutgoGraph team. When filing the bug, set the verbosity to 10 (on Linux, `export AUTOGRAPH_VERBOSITY=10`) and attach the full output. Cause: converting <bound method BatchNormalization.call of <tensorflow.python.layers.normalization.BatchNormalization object at 0x00000262158996A0>>: AssertionError: Bad argument number for Name: 3, expecting 4
2020-12-22 18:12:35 Entity <bound method Conv.call of <tensorflow.python.layers.convolutional.Conv2D object at 0x0000026215940898>> could not be transformed and will be executed as-is. Please report this to the AutgoGraph team. When filing the bug, set the verbosity to 10 (on Linux, `export AUTOGRAPH_VERBOSITY=10`) and attach the full output. Cause: converting <bound method Conv.call of <tensorflow.python.layers.convolutional.Conv2D object at 0x0000026215940898>>: AssertionError: Bad argument number for Name: 3, expecting 4
2020-12-22 18:12:35 Entity <bound method BatchNormalization.call of <tensorflow.python.layers.normalization.BatchNormalization object at 0x00000262159D71D0>> could not be transformed and will be executed as-is. Please report this to the AutgoGraph team. When filing the bug, set the verbosity to 10 (on Linux, `export AUTOGRAPH_VERBOSITY=10`) and attach the full output. Cause: converting <bound method BatchNormalization.call of <tensorflow.python.layers.normalization.BatchNormalization object at 0x00000262159D71D0>>: AssertionError: Bad argument number for Name: 3, expecting 4
2020-12-22 18:12:35 Entity <bound method Conv.call of <tensorflow.python.layers.convolutional.Conv2D object at 0x00000262159B4B70>> could not be transformed and will be executed as-is. Please report this to the AutgoGraph team. When filing the bug, set the verbosity to 10 (on Linux, `export AUTOGRAPH_VERBOSITY=10`) and attach the full output. Cause: converting <bound method Conv.call of <tensorflow.python.layers.convolutional.Conv2D object at 0x00000262159B4B70>>: AssertionError: Bad argument number for Name: 3, expecting 4
2020-12-22 18:12:35 Entity <bound method BatchNormalization.call of <tensorflow.python.layers.normalization.BatchNormalization object at 0x0000026215899A20>> could not be transformed and will be executed as-is. Please report this to the AutgoGraph team. When filing the bug, set the verbosity to 10 (on Linux, `export AUTOGRAPH_VERBOSITY=10`) and attach the full output. Cause: converting <bound method BatchNormalization.call of <tensorflow.python.layers.normalization.BatchNormalization object at 0x0000026215899A20>>: AssertionError: Bad argument number for Name: 3, expecting 4
2020-12-22 18:12:35 Entity <bound method Conv.call of <tensorflow.python.layers.convolutional.Conv2D object at 0x00000262159646D8>> could not be transformed and will be executed as-is. Please report this to the AutgoGraph team. When filing the bug, set the verbosity to 10 (on Linux, `export AUTOGRAPH_VERBOSITY=10`) and attach the full output. Cause: converting <bound method Conv.call of <tensorflow.python.layers.convolutional.Conv2D object at 0x00000262159646D8>>: AssertionError: Bad argument number for Name: 3, expecting 4
2020-12-22 18:12:35 Entity <bound method BatchNormalization.call of <tensorflow.python.layers.normalization.BatchNormalization object at 0x0000026215A87C88>> could not be transformed and will be executed as-is. Please report this to the AutgoGraph team. When filing the bug, set the verbosity to 10 (on Linux, `export AUTOGRAPH_VERBOSITY=10`) and attach the full output. Cause: converting <bound method BatchNormalization.call of <tensorflow.python.layers.normalization.BatchNormalization object at 0x0000026215A87C88>>: AssertionError: Bad argument number for Name: 3, expecting 4
2020-12-22 18:12:35 Entity <bound method Conv.call of <tensorflow.python.layers.convolutional.Conv2D object at 0x0000026215A268D0>> could not be transformed and will be executed as-is. Please report this to the AutgoGraph team. When filing the bug, set the verbosity to 10 (on Linux, `export AUTOGRAPH_VERBOSITY=10`) and attach the full output. Cause: converting <bound method Conv.call of <tensorflow.python.layers.convolutional.Conv2D object at 0x0000026215A268D0>>: AssertionError: Bad argument number for Name: 3, expecting 4
2020-12-22 18:12:35 Entity <bound method BatchNormalization.call of <tensorflow.python.layers.normalization.BatchNormalization object at 0x0000026215AB9D68>> could not be transformed and will be executed as-is. Please report this to the AutgoGraph team. When filing the bug, set the verbosity to 10 (on Linux, `export AUTOGRAPH_VERBOSITY=10`) and attach the full output. Cause: converting <bound method BatchNormalization.call of <tensorflow.python.layers.normalization.BatchNormalization object at 0x0000026215AB9D68>>: AssertionError: Bad argument number for Name: 3, expecting 4
2020-12-22 18:12:35 Entity <bound method Conv.call of <tensorflow.python.layers.convolutional.Conv2D object at 0x00000262159D7630>> could not be transformed and will be executed as-is. Please report this to the AutgoGraph team. When filing the bug, set the verbosity to 10 (on Linux, `export AUTOGRAPH_VERBOSITY=10`) and attach the full output. Cause: converting <bound method Conv.call of <tensorflow.python.layers.convolutional.Conv2D object at 0x00000262159D7630>>: AssertionError: Bad argument number for Name: 3, expecting 4
2020-12-22 18:12:35 Entity <bound method BatchNormalization.call of <tensorflow.python.layers.normalization.BatchNormalization object at 0x000002621597ADA0>> could not be transformed and will be executed as-is. Please report this to the AutgoGraph team. When filing the bug, set the verbosity to 10 (on Linux, `export AUTOGRAPH_VERBOSITY=10`) and attach the full output. Cause: converting <bound method BatchNormalization.call of <tensorflow.python.layers.normalization.BatchNormalization object at 0x000002621597ADA0>>: AssertionError: Bad argument number for Name: 3, expecting 4
2020-12-22 18:12:35 Entity <bound method Conv.call of <tensorflow.python.layers.convolutional.Conv2D object at 0x00000262159646D8>> could not be transformed and will be executed as-is. Please report this to the AutgoGraph team. When filing the bug, set the verbosity to 10 (on Linux, `export AUTOGRAPH_VERBOSITY=10`) and attach the full output. Cause: converting <bound method Conv.call of <tensorflow.python.layers.convolutional.Conv2D object at 0x00000262159646D8>>: AssertionError: Bad argument number for Name: 3, expecting 4
2020-12-22 18:12:35 Entity <bound method BatchNormalization.call of <tensorflow.python.layers.normalization.BatchNormalization object at 0x0000026215B564E0>> could not be transformed and will be executed as-is. Please report this to the AutgoGraph team. When filing the bug, set the verbosity to 10 (on Linux, `export AUTOGRAPH_VERBOSITY=10`) and attach the full output. Cause: converting <bound method BatchNormalization.call of <tensorflow.python.layers.normalization.BatchNormalization object at 0x0000026215B564E0>>: AssertionError: Bad argument number for Name: 3, expecting 4
2020-12-22 18:12:36 Entity <bound method Conv.call of <tensorflow.python.layers.convolutional.Conv2D object at 0x0000026215B3AEF0>> could not be transformed and will be executed as-is. Please report this to the AutgoGraph team. When filing the bug, set the verbosity to 10 (on Linux, `export AUTOGRAPH_VERBOSITY=10`) and attach the full output. Cause: converting <bound method Conv.call of <tensorflow.python.layers.convolutional.Conv2D object at 0x0000026215B3AEF0>>: AssertionError: Bad argument number for Name: 3, expecting 4
2020-12-22 18:12:36 Entity <bound method BatchNormalization.call of <tensorflow.python.layers.normalization.BatchNormalization object at 0x0000026215A876A0>> could not be transformed and will be executed as-is. Please report this to the AutgoGraph team. When filing the bug, set the verbosity to 10 (on Linux, `export AUTOGRAPH_VERBOSITY=10`) and attach the full output. Cause: converting <bound method BatchNormalization.call of <tensorflow.python.layers.normalization.BatchNormalization object at 0x0000026215A876A0>>: AssertionError: Bad argument number for Name: 3, expecting 4
2020-12-22 18:12:36 Entity <bound method Conv.call of <tensorflow.python.layers.convolutional.Conv2D object at 0x0000026215A4EB38>> could not be transformed and will be executed as-is. Please report this to the AutgoGraph team. When filing the bug, set the verbosity to 10 (on Linux, `export AUTOGRAPH_VERBOSITY=10`) and attach the full output. Cause: converting <bound method Conv.call of <tensorflow.python.layers.convolutional.Conv2D object at 0x0000026215A4EB38>>: AssertionError: Bad argument number for Name: 3, expecting 4
2020-12-22 18:12:36 Entity <bound method BatchNormalization.call of <tensorflow.python.layers.normalization.BatchNormalization object at 0x0000026215AB9B38>> could not be transformed and will be executed as-is. Please report this to the AutgoGraph team. When filing the bug, set the verbosity to 10 (on Linux, `export AUTOGRAPH_VERBOSITY=10`) and attach the full output. Cause: converting <bound method BatchNormalization.call of <tensorflow.python.layers.normalization.BatchNormalization object at 0x0000026215AB9B38>>: AssertionError: Bad argument number for Name: 3, expecting 4
2020-12-22 18:12:36 Entity <bound method Pooling2D.call of <tensorflow.python.layers.pooling.MaxPooling2D object at 0x0000026215B0F0F0>> could not be transformed and will be executed as-is. Please report this to the AutgoGraph team. When filing the bug, set the verbosity to 10 (on Linux, `export AUTOGRAPH_VERBOSITY=10`) and attach the full output. Cause: converting <bound method Pooling2D.call of <tensorflow.python.layers.pooling.MaxPooling2D object at 0x0000026215B0F0F0>>: AssertionError: Bad argument number for Name: 3, expecting 4
2020-12-22 18:12:36 Entity <bound method Conv.call of <tensorflow.python.layers.convolutional.Conv2D object at 0x0000026215B8BDD8>> could not be transformed and will be executed as-is. Please report this to the AutgoGraph team. When filing the bug, set the verbosity to 10 (on Linux, `export AUTOGRAPH_VERBOSITY=10`) and attach the full output. Cause: converting <bound method Conv.call of <tensorflow.python.layers.convolutional.Conv2D object at 0x0000026215B8BDD8>>: AssertionError: Bad argument number for Name: 3, expecting 4
2020-12-22 18:12:36 Entity <bound method BatchNormalization.call of <tensorflow.python.layers.normalization.BatchNormalization object at 0x0000026215C71D30>> could not be transformed and will be executed as-is. Please report this to the AutgoGraph team. When filing the bug, set the verbosity to 10 (on Linux, `export AUTOGRAPH_VERBOSITY=10`) and attach the full output. Cause: converting <bound method BatchNormalization.call of <tensorflow.python.layers.normalization.BatchNormalization object at 0x0000026215C71D30>>: AssertionError: Bad argument number for Name: 3, expecting 4
2020-12-22 18:12:36 Entity <bound method Conv.call of <tensorflow.python.layers.convolutional.Conv2D object at 0x0000026215C3B7B8>> could not be transformed and will be executed as-is. Please report this to the AutgoGraph team. When filing the bug, set the verbosity to 10 (on Linux, `export AUTOGRAPH_VERBOSITY=10`) and attach the full output. Cause: converting <bound method Conv.call of <tensorflow.python.layers.convolutional.Conv2D object at 0x0000026215C3B7B8>>: AssertionError: Bad argument number for Name: 3, expecting 4
2020-12-22 18:12:36 Entity <bound method BatchNormalization.call of <tensorflow.python.layers.normalization.BatchNormalization object at 0x0000026215CFAEB8>> could not be transformed and will be executed as-is. Please report this to the AutgoGraph team. When filing the bug, set the verbosity to 10 (on Linux, `export AUTOGRAPH_VERBOSITY=10`) and attach the full output. Cause: converting <bound method BatchNormalization.call of <tensorflow.python.layers.normalization.BatchNormalization object at 0x0000026215CFAEB8>>: AssertionError: Bad argument number for Name: 3, expecting 4
2020-12-22 18:12:36 Entity <bound method Conv.call of <tensorflow.python.layers.convolutional.Conv2D object at 0x0000026215C71BE0>> could not be transformed and will be executed as-is. Please report this to the AutgoGraph team. When filing the bug, set the verbosity to 10 (on Linux, `export AUTOGRAPH_VERBOSITY=10`) and attach the full output. Cause: converting <bound method Conv.call of <tensorflow.python.layers.convolutional.Conv2D object at 0x0000026215C71BE0>>: AssertionError: Bad argument number for Name: 3, expecting 4
2020-12-22 18:12:36 Entity <bound method BatchNormalization.call of <tensorflow.python.layers.normalization.BatchNormalization object at 0x0000026215CF8F28>> could not be transformed and will be executed as-is. Please report this to the AutgoGraph team. When filing the bug, set the verbosity to 10 (on Linux, `export AUTOGRAPH_VERBOSITY=10`) and attach the full output. Cause: converting <bound method BatchNormalization.call of <tensorflow.python.layers.normalization.BatchNormalization object at 0x0000026215CF8F28>>: AssertionError: Bad argument number for Name: 3, expecting 4
2020-12-22 18:12:37 Entity <bound method Conv.call of <tensorflow.python.layers.convolutional.Conv2D object at 0x0000026215C719B0>> could not be transformed and will be executed as-is. Please report this to the AutgoGraph team. When filing the bug, set the verbosity to 10 (on Linux, `export AUTOGRAPH_VERBOSITY=10`) and attach the full output. Cause: converting <bound method Conv.call of <tensorflow.python.layers.convolutional.Conv2D object at 0x0000026215C719B0>>: AssertionError: Bad argument number for Name: 3, expecting 4
2020-12-22 18:12:37 Entity <bound method BatchNormalization.call of <tensorflow.python.layers.normalization.BatchNormalization object at 0x0000026215B56390>> could not be transformed and will be executed as-is. Please report this to the AutgoGraph team. When filing the bug, set the verbosity to 10 (on Linux, `export AUTOGRAPH_VERBOSITY=10`) and attach the full output. Cause: converting <bound method BatchNormalization.call of <tensorflow.python.layers.normalization.BatchNormalization object at 0x0000026215B56390>>: AssertionError: Bad argument number for Name: 3, expecting 4
2020-12-22 18:12:37 Entity <bound method Conv.call of <tensorflow.python.layers.convolutional.Conv2D object at 0x00000262155C5358>> could not be transformed and will be executed as-is. Please report this to the AutgoGraph team. When filing the bug, set the verbosity to 10 (on Linux, `export AUTOGRAPH_VERBOSITY=10`) and attach the full output. Cause: converting <bound method Conv.call of <tensorflow.python.layers.convolutional.Conv2D object at 0x00000262155C5358>>: AssertionError: Bad argument number for Name: 3, expecting 4
2020-12-22 18:12:37 Entity <bound method BatchNormalization.call of <tensorflow.python.layers.normalization.BatchNormalization object at 0x0000026215D73B70>> could not be transformed and will be executed as-is. Please report this to the AutgoGraph team. When filing the bug, set the verbosity to 10 (on Linux, `export AUTOGRAPH_VERBOSITY=10`) and attach the full output. Cause: converting <bound method BatchNormalization.call of <tensorflow.python.layers.normalization.BatchNormalization object at 0x0000026215D73B70>>: AssertionError: Bad argument number for Name: 3, expecting 4
2020-12-22 18:12:37 Entity <bound method Conv.call of <tensorflow.python.layers.convolutional.Conv2D object at 0x0000026215CBF4A8>> could not be transformed and will be executed as-is. Please report this to the AutgoGraph team. When filing the bug, set the verbosity to 10 (on Linux, `export AUTOGRAPH_VERBOSITY=10`) and attach the full output. Cause: converting <bound method Conv.call of <tensorflow.python.layers.convolutional.Conv2D object at 0x0000026215CBF4A8>>: AssertionError: Bad argument number for Name: 3, expecting 4
2020-12-22 18:12:37 Entity <bound method BatchNormalization.call of <tensorflow.python.layers.normalization.BatchNormalization object at 0x0000026215DBBC88>> could not be transformed and will be executed as-is. Please report this to the AutgoGraph team. When filing the bug, set the verbosity to 10 (on Linux, `export AUTOGRAPH_VERBOSITY=10`) and attach the full output. Cause: converting <bound method BatchNormalization.call of <tensorflow.python.layers.normalization.BatchNormalization object at 0x0000026215DBBC88>>: AssertionError: Bad argument number for Name: 3, expecting 4
2020-12-22 18:12:37 Entity <bound method Conv.call of <tensorflow.python.layers.convolutional.Conv2D object at 0x00000262159D7630>> could not be transformed and will be executed as-is. Please report this to the AutgoGraph team. When filing the bug, set the verbosity to 10 (on Linux, `export AUTOGRAPH_VERBOSITY=10`) and attach the full output. Cause: converting <bound method Conv.call of <tensorflow.python.layers.convolutional.Conv2D object at 0x00000262159D7630>>: AssertionError: Bad argument number for Name: 3, expecting 4
2020-12-22 18:12:37 Entity <bound method BatchNormalization.call of <tensorflow.python.layers.normalization.BatchNormalization object at 0x0000026215CBFA20>> could not be transformed and will be executed as-is. Please report this to the AutgoGraph team. When filing the bug, set the verbosity to 10 (on Linux, `export AUTOGRAPH_VERBOSITY=10`) and attach the full output. Cause: converting <bound method BatchNormalization.call of <tensorflow.python.layers.normalization.BatchNormalization object at 0x0000026215CBFA20>>: AssertionError: Bad argument number for Name: 3, expecting 4
2020-12-22 18:12:37 Entity <bound method Conv.call of <tensorflow.python.layers.convolutional.Conv2D object at 0x0000026215B56D68>> could not be transformed and will be executed as-is. Please report this to the AutgoGraph team. When filing the bug, set the verbosity to 10 (on Linux, `export AUTOGRAPH_VERBOSITY=10`) and attach the full output. Cause: converting <bound method Conv.call of <tensorflow.python.layers.convolutional.Conv2D object at 0x0000026215B56D68>>: AssertionError: Bad argument number for Name: 3, expecting 4
2020-12-22 18:12:37 Entity <bound method BatchNormalization.call of <tensorflow.python.layers.normalization.BatchNormalization object at 0x0000026215E4AA58>> could not be transformed and will be executed as-is. Please report this to the AutgoGraph team. When filing the bug, set the verbosity to 10 (on Linux, `export AUTOGRAPH_VERBOSITY=10`) and attach the full output. Cause: converting <bound method BatchNormalization.call of <tensorflow.python.layers.normalization.BatchNormalization object at 0x0000026215E4AA58>>: AssertionError: Bad argument number for Name: 3, expecting 4
2020-12-22 18:12:37 Entity <bound method Conv.call of <tensorflow.python.layers.convolutional.Conv2D object at 0x0000026215CD7828>> could not be transformed and will be executed as-is. Please report this to the AutgoGraph team. When filing the bug, set the verbosity to 10 (on Linux, `export AUTOGRAPH_VERBOSITY=10`) and attach the full output. Cause: converting <bound method Conv.call of <tensorflow.python.layers.convolutional.Conv2D object at 0x0000026215CD7828>>: AssertionError: Bad argument number for Name: 3, expecting 4
2020-12-22 18:12:38 Entity <bound method BatchNormalization.call of <tensorflow.python.layers.normalization.BatchNormalization object at 0x0000026215F158D0>> could not be transformed and will be executed as-is. Please report this to the AutgoGraph team. When filing the bug, set the verbosity to 10 (on Linux, `export AUTOGRAPH_VERBOSITY=10`) and attach the full output. Cause: converting <bound method BatchNormalization.call of <tensorflow.python.layers.normalization.BatchNormalization object at 0x0000026215F158D0>>: AssertionError: Bad argument number for Name: 3, expecting 4
2020-12-22 18:12:38 Entity <bound method Conv.call of <tensorflow.python.layers.convolutional.Conv2D object at 0x0000026215D52FD0>> could not be transformed and will be executed as-is. Please report this to the AutgoGraph team. When filing the bug, set the verbosity to 10 (on Linux, `export AUTOGRAPH_VERBOSITY=10`) and attach the full output. Cause: converting <bound method Conv.call of <tensorflow.python.layers.convolutional.Conv2D object at 0x0000026215D52FD0>>: AssertionError: Bad argument number for Name: 3, expecting 4
2020-12-22 18:12:38 Entity <bound method BatchNormalization.call of <tensorflow.python.layers.normalization.BatchNormalization object at 0x000002621597ACF8>> could not be transformed and will be executed as-is. Please report this to the AutgoGraph team. When filing the bug, set the verbosity to 10 (on Linux, `export AUTOGRAPH_VERBOSITY=10`) and attach the full output. Cause: converting <bound method BatchNormalization.call of <tensorflow.python.layers.normalization.BatchNormalization object at 0x000002621597ACF8>>: AssertionError: Bad argument number for Name: 3, expecting 4
2020-12-22 18:12:38 Entity <bound method Conv.call of <tensorflow.python.layers.convolutional.Conv2D object at 0x0000026215E6BA90>> could not be transformed and will be executed as-is. Please report this to the AutgoGraph team. When filing the bug, set the verbosity to 10 (on Linux, `export AUTOGRAPH_VERBOSITY=10`) and attach the full output. Cause: converting <bound method Conv.call of <tensorflow.python.layers.convolutional.Conv2D object at 0x0000026215E6BA90>>: AssertionError: Bad argument number for Name: 3, expecting 4
2020-12-22 18:12:38 Entity <bound method BatchNormalization.call of <tensorflow.python.layers.normalization.BatchNormalization object at 0x0000026215DBBB00>> could not be transformed and will be executed as-is. Please report this to the AutgoGraph team. When filing the bug, set the verbosity to 10 (on Linux, `export AUTOGRAPH_VERBOSITY=10`) and attach the full output. Cause: converting <bound method BatchNormalization.call of <tensorflow.python.layers.normalization.BatchNormalization object at 0x0000026215DBBB00>>: AssertionError: Bad argument number for Name: 3, expecting 4
2020-12-22 18:12:38 Entity <bound method Conv.call of <tensorflow.python.layers.convolutional.Conv2D object at 0x0000026215E98B70>> could not be transformed and will be executed as-is. Please report this to the AutgoGraph team. When filing the bug, set the verbosity to 10 (on Linux, `export AUTOGRAPH_VERBOSITY=10`) and attach the full output. Cause: converting <bound method Conv.call of <tensorflow.python.layers.convolutional.Conv2D object at 0x0000026215E98B70>>: AssertionError: Bad argument number for Name: 3, expecting 4
2020-12-22 18:12:38 Entity <bound method BatchNormalization.call of <tensorflow.python.layers.normalization.BatchNormalization object at 0x0000026215E1B550>> could not be transformed and will be executed as-is. Please report this to the AutgoGraph team. When filing the bug, set the verbosity to 10 (on Linux, `export AUTOGRAPH_VERBOSITY=10`) and attach the full output. Cause: converting <bound method BatchNormalization.call of <tensorflow.python.layers.normalization.BatchNormalization object at 0x0000026215E1B550>>: AssertionError: Bad argument number for Name: 3, expecting 4
2020-12-22 18:12:38 Entity <bound method Conv.call of <tensorflow.python.layers.convolutional.Conv2D object at 0x0000026215E989E8>> could not be transformed and will be executed as-is. Please report this to the AutgoGraph team. When filing the bug, set the verbosity to 10 (on Linux, `export AUTOGRAPH_VERBOSITY=10`) and attach the full output. Cause: converting <bound method Conv.call of <tensorflow.python.layers.convolutional.Conv2D object at 0x0000026215E989E8>>: AssertionError: Bad argument number for Name: 3, expecting 4
2020-12-22 18:12:38 Entity <bound method BatchNormalization.call of <tensorflow.python.layers.normalization.BatchNormalization object at 0x0000026216036550>> could not be transformed and will be executed as-is. Please report this to the AutgoGraph team. When filing the bug, set the verbosity to 10 (on Linux, `export AUTOGRAPH_VERBOSITY=10`) and attach the full output. Cause: converting <bound method BatchNormalization.call of <tensorflow.python.layers.normalization.BatchNormalization object at 0x0000026216036550>>: AssertionError: Bad argument number for Name: 3, expecting 4
2020-12-22 18:12:38 Entity <bound method Conv.call of <tensorflow.python.layers.convolutional.Conv2D object at 0x0000026215F95860>> could not be transformed and will be executed as-is. Please report this to the AutgoGraph team. When filing the bug, set the verbosity to 10 (on Linux, `export AUTOGRAPH_VERBOSITY=10`) and attach the full output. Cause: converting <bound method Conv.call of <tensorflow.python.layers.convolutional.Conv2D object at 0x0000026215F95860>>: AssertionError: Bad argument number for Name: 3, expecting 4
2020-12-22 18:12:38 Entity <bound method BatchNormalization.call of <tensorflow.python.layers.normalization.BatchNormalization object at 0x0000026216085048>> could not be transformed and will be executed as-is. Please report this to the AutgoGraph team. When filing the bug, set the verbosity to 10 (on Linux, `export AUTOGRAPH_VERBOSITY=10`) and attach the full output. Cause: converting <bound method BatchNormalization.call of <tensorflow.python.layers.normalization.BatchNormalization object at 0x0000026216085048>>: AssertionError: Bad argument number for Name: 3, expecting 4
2020-12-22 18:12:39 Entity <bound method Conv.call of <tensorflow.python.layers.convolutional.Conv2D object at 0x0000026216058048>> could not be transformed and will be executed as-is. Please report this to the AutgoGraph team. When filing the bug, set the verbosity to 10 (on Linux, `export AUTOGRAPH_VERBOSITY=10`) and attach the full output. Cause: converting <bound method Conv.call of <tensorflow.python.layers.convolutional.Conv2D object at 0x0000026216058048>>: AssertionError: Bad argument number for Name: 3, expecting 4
2020-12-22 18:12:39 Entity <bound method BatchNormalization.call of <tensorflow.python.layers.normalization.BatchNormalization object at 0x0000026215E25BA8>> could not be transformed and will be executed as-is. Please report this to the AutgoGraph team. When filing the bug, set the verbosity to 10 (on Linux, `export AUTOGRAPH_VERBOSITY=10`) and attach the full output. Cause: converting <bound method BatchNormalization.call of <tensorflow.python.layers.normalization.BatchNormalization object at 0x0000026215E25BA8>>: AssertionError: Bad argument number for Name: 3, expecting 4
2020-12-22 18:12:39 Entity <bound method Conv.call of <tensorflow.python.layers.convolutional.Conv2D object at 0x0000026215FA82E8>> could not be transformed and will be executed as-is. Please report this to the AutgoGraph team. When filing the bug, set the verbosity to 10 (on Linux, `export AUTOGRAPH_VERBOSITY=10`) and attach the full output. Cause: converting <bound method Conv.call of <tensorflow.python.layers.convolutional.Conv2D object at 0x0000026215FA82E8>>: AssertionError: Bad argument number for Name: 3, expecting 4
2020-12-22 18:12:39 Entity <bound method BatchNormalization.call of <tensorflow.python.layers.normalization.BatchNormalization object at 0x000002621610A2B0>> could not be transformed and will be executed as-is. Please report this to the AutgoGraph team. When filing the bug, set the verbosity to 10 (on Linux, `export AUTOGRAPH_VERBOSITY=10`) and attach the full output. Cause: converting <bound method BatchNormalization.call of <tensorflow.python.layers.normalization.BatchNormalization object at 0x000002621610A2B0>>: AssertionError: Bad argument number for Name: 3, expecting 4
2020-12-22 18:12:39 Entity <bound method Conv.call of <tensorflow.python.layers.convolutional.Conv2D object at 0x0000026215E989E8>> could not be transformed and will be executed as-is. Please report this to the AutgoGraph team. When filing the bug, set the verbosity to 10 (on Linux, `export AUTOGRAPH_VERBOSITY=10`) and attach the full output. Cause: converting <bound method Conv.call of <tensorflow.python.layers.convolutional.Conv2D object at 0x0000026215E989E8>>: AssertionError: Bad argument number for Name: 3, expecting 4
2020-12-22 18:12:39 Entity <bound method BatchNormalization.call of <tensorflow.python.layers.normalization.BatchNormalization object at 0x0000026215F59860>> could not be transformed and will be executed as-is. Please report this to the AutgoGraph team. When filing the bug, set the verbosity to 10 (on Linux, `export AUTOGRAPH_VERBOSITY=10`) and attach the full output. Cause: converting <bound method BatchNormalization.call of <tensorflow.python.layers.normalization.BatchNormalization object at 0x0000026215F59860>>: AssertionError: Bad argument number for Name: 3, expecting 4
2020-12-22 18:12:39 Entity <bound method Conv.call of <tensorflow.python.layers.convolutional.Conv2D object at 0x0000026216058048>> could not be transformed and will be executed as-is. Please report this to the AutgoGraph team. When filing the bug, set the verbosity to 10 (on Linux, `export AUTOGRAPH_VERBOSITY=10`) and attach the full output. Cause: converting <bound method Conv.call of <tensorflow.python.layers.convolutional.Conv2D object at 0x0000026216058048>>: AssertionError: Bad argument number for Name: 3, expecting 4
2020-12-22 18:12:39 Entity <bound method BatchNormalization.call of <tensorflow.python.layers.normalization.BatchNormalization object at 0x0000026216187CC0>> could not be transformed and will be executed as-is. Please report this to the AutgoGraph team. When filing the bug, set the verbosity to 10 (on Linux, `export AUTOGRAPH_VERBOSITY=10`) and attach the full output. Cause: converting <bound method BatchNormalization.call of <tensorflow.python.layers.normalization.BatchNormalization object at 0x0000026216187CC0>>: AssertionError: Bad argument number for Name: 3, expecting 4
2020-12-22 18:12:39 Entity <bound method Conv.call of <tensorflow.python.layers.convolutional.Conv2D object at 0x0000026215E4AB00>> could not be transformed and will be executed as-is. Please report this to the AutgoGraph team. When filing the bug, set the verbosity to 10 (on Linux, `export AUTOGRAPH_VERBOSITY=10`) and attach the full output. Cause: converting <bound method Conv.call of <tensorflow.python.layers.convolutional.Conv2D object at 0x0000026215E4AB00>>: AssertionError: Bad argument number for Name: 3, expecting 4
2020-12-22 18:12:39 Entity <bound method BatchNormalization.call of <tensorflow.python.layers.normalization.BatchNormalization object at 0x00000262160A4B70>> could not be transformed and will be executed as-is. Please report this to the AutgoGraph team. When filing the bug, set the verbosity to 10 (on Linux, `export AUTOGRAPH_VERBOSITY=10`) and attach the full output. Cause: converting <bound method BatchNormalization.call of <tensorflow.python.layers.normalization.BatchNormalization object at 0x00000262160A4B70>>: AssertionError: Bad argument number for Name: 3, expecting 4
2020-12-22 18:12:39 Entity <bound method Conv.call of <tensorflow.python.layers.convolutional.Conv2D object at 0x0000026215E1B668>> could not be transformed and will be executed as-is. Please report this to the AutgoGraph team. When filing the bug, set the verbosity to 10 (on Linux, `export AUTOGRAPH_VERBOSITY=10`) and attach the full output. Cause: converting <bound method Conv.call of <tensorflow.python.layers.convolutional.Conv2D object at 0x0000026215E1B668>>: AssertionError: Bad argument number for Name: 3, expecting 4
2020-12-22 18:12:39 Entity <bound method BatchNormalization.call of <tensorflow.python.layers.normalization.BatchNormalization object at 0x0000026216285DD8>> could not be transformed and will be executed as-is. Please report this to the AutgoGraph team. When filing the bug, set the verbosity to 10 (on Linux, `export AUTOGRAPH_VERBOSITY=10`) and attach the full output. Cause: converting <bound method BatchNormalization.call of <tensorflow.python.layers.normalization.BatchNormalization object at 0x0000026216285DD8>>: AssertionError: Bad argument number for Name: 3, expecting 4
2020-12-22 18:12:39 Entity <bound method Conv.call of <tensorflow.python.layers.convolutional.Conv2D object at 0x00000262160EB828>> could not be transformed and will be executed as-is. Please report this to the AutgoGraph team. When filing the bug, set the verbosity to 10 (on Linux, `export AUTOGRAPH_VERBOSITY=10`) and attach the full output. Cause: converting <bound method Conv.call of <tensorflow.python.layers.convolutional.Conv2D object at 0x00000262160EB828>>: AssertionError: Bad argument number for Name: 3, expecting 4
2020-12-22 18:12:40 Entity <bound method BatchNormalization.call of <tensorflow.python.layers.normalization.BatchNormalization object at 0x000002621629E0F0>> could not be transformed and will be executed as-is. Please report this to the AutgoGraph team. When filing the bug, set the verbosity to 10 (on Linux, `export AUTOGRAPH_VERBOSITY=10`) and attach the full output. Cause: converting <bound method BatchNormalization.call of <tensorflow.python.layers.normalization.BatchNormalization object at 0x000002621629E0F0>>: AssertionError: Bad argument number for Name: 3, expecting 4
2020-12-22 18:12:40 Entity <bound method Conv.call of <tensorflow.python.layers.convolutional.Conv2D object at 0x0000026215F59B38>> could not be transformed and will be executed as-is. Please report this to the AutgoGraph team. When filing the bug, set the verbosity to 10 (on Linux, `export AUTOGRAPH_VERBOSITY=10`) and attach the full output. Cause: converting <bound method Conv.call of <tensorflow.python.layers.convolutional.Conv2D object at 0x0000026215F59B38>>: AssertionError: Bad argument number for Name: 3, expecting 4
2020-12-22 18:12:40 Entity <bound method BatchNormalization.call of <tensorflow.python.layers.normalization.BatchNormalization object at 0x00000262161C2F28>> could not be transformed and will be executed as-is. Please report this to the AutgoGraph team. When filing the bug, set the verbosity to 10 (on Linux, `export AUTOGRAPH_VERBOSITY=10`) and attach the full output. Cause: converting <bound method BatchNormalization.call of <tensorflow.python.layers.normalization.BatchNormalization object at 0x00000262161C2F28>>: AssertionError: Bad argument number for Name: 3, expecting 4
2020-12-22 18:12:40 Entity <bound method Conv.call of <tensorflow.python.layers.convolutional.Conv2D object at 0x00000262161B9F98>> could not be transformed and will be executed as-is. Please report this to the AutgoGraph team. When filing the bug, set the verbosity to 10 (on Linux, `export AUTOGRAPH_VERBOSITY=10`) and attach the full output. Cause: converting <bound method Conv.call of <tensorflow.python.layers.convolutional.Conv2D object at 0x00000262161B9F98>>: AssertionError: Bad argument number for Name: 3, expecting 4
2020-12-22 18:12:40 Entity <bound method BatchNormalization.call of <tensorflow.python.layers.normalization.BatchNormalization object at 0x000002621629E128>> could not be transformed and will be executed as-is. Please report this to the AutgoGraph team. When filing the bug, set the verbosity to 10 (on Linux, `export AUTOGRAPH_VERBOSITY=10`) and attach the full output. Cause: converting <bound method BatchNormalization.call of <tensorflow.python.layers.normalization.BatchNormalization object at 0x000002621629E128>>: AssertionError: Bad argument number for Name: 3, expecting 4
2020-12-22 18:12:40 Entity <bound method Conv.call of <tensorflow.python.layers.convolutional.Conv2D object at 0x0000026216239BE0>> could not be transformed and will be executed as-is. Please report this to the AutgoGraph team. When filing the bug, set the verbosity to 10 (on Linux, `export AUTOGRAPH_VERBOSITY=10`) and attach the full output. Cause: converting <bound method Conv.call of <tensorflow.python.layers.convolutional.Conv2D object at 0x0000026216239BE0>>: AssertionError: Bad argument number for Name: 3, expecting 4
2020-12-22 18:12:40 Entity <bound method BatchNormalization.call of <tensorflow.python.layers.normalization.BatchNormalization object at 0x00000262162E4BE0>> could not be transformed and will be executed as-is. Please report this to the AutgoGraph team. When filing the bug, set the verbosity to 10 (on Linux, `export AUTOGRAPH_VERBOSITY=10`) and attach the full output. Cause: converting <bound method BatchNormalization.call of <tensorflow.python.layers.normalization.BatchNormalization object at 0x00000262162E4BE0>>: AssertionError: Bad argument number for Name: 3, expecting 4
2020-12-22 18:12:40 Entity <bound method Conv.call of <tensorflow.python.layers.convolutional.Conv2D object at 0x0000026216285A90>> could not be transformed and will be executed as-is. Please report this to the AutgoGraph team. When filing the bug, set the verbosity to 10 (on Linux, `export AUTOGRAPH_VERBOSITY=10`) and attach the full output. Cause: converting <bound method Conv.call of <tensorflow.python.layers.convolutional.Conv2D object at 0x0000026216285A90>>: AssertionError: Bad argument number for Name: 3, expecting 4
2020-12-22 18:12:40 Entity <bound method BatchNormalization.call of <tensorflow.python.layers.normalization.BatchNormalization object at 0x00000262162E4BE0>> could not be transformed and will be executed as-is. Please report this to the AutgoGraph team. When filing the bug, set the verbosity to 10 (on Linux, `export AUTOGRAPH_VERBOSITY=10`) and attach the full output. Cause: converting <bound method BatchNormalization.call of <tensorflow.python.layers.normalization.BatchNormalization object at 0x00000262162E4BE0>>: AssertionError: Bad argument number for Name: 3, expecting 4
2020-12-22 18:12:40 Entity <bound method Conv.call of <tensorflow.python.layers.convolutional.Conv2D object at 0x00000262162E4BE0>> could not be transformed and will be executed as-is. Please report this to the AutgoGraph team. When filing the bug, set the verbosity to 10 (on Linux, `export AUTOGRAPH_VERBOSITY=10`) and attach the full output. Cause: converting <bound method Conv.call of <tensorflow.python.layers.convolutional.Conv2D object at 0x00000262162E4BE0>>: AssertionError: Bad argument number for Name: 3, expecting 4
2020-12-22 18:12:40 Entity <bound method BatchNormalization.call of <tensorflow.python.layers.normalization.BatchNormalization object at 0x0000026215685E80>> could not be transformed and will be executed as-is. Please report this to the AutgoGraph team. When filing the bug, set the verbosity to 10 (on Linux, `export AUTOGRAPH_VERBOSITY=10`) and attach the full output. Cause: converting <bound method BatchNormalization.call of <tensorflow.python.layers.normalization.BatchNormalization object at 0x0000026215685E80>>: AssertionError: Bad argument number for Name: 3, expecting 4
2020-12-22 18:12:41 Entity <bound method Conv.call of <tensorflow.python.layers.convolutional.Conv2D object at 0x0000026216239A20>> could not be transformed and will be executed as-is. Please report this to the AutgoGraph team. When filing the bug, set the verbosity to 10 (on Linux, `export AUTOGRAPH_VERBOSITY=10`) and attach the full output. Cause: converting <bound method Conv.call of <tensorflow.python.layers.convolutional.Conv2D object at 0x0000026216239A20>>: AssertionError: Bad argument number for Name: 3, expecting 4
2020-12-22 18:12:41 Entity <bound method BatchNormalization.call of <tensorflow.python.layers.normalization.BatchNormalization object at 0x0000026216239F28>> could not be transformed and will be executed as-is. Please report this to the AutgoGraph team. When filing the bug, set the verbosity to 10 (on Linux, `export AUTOGRAPH_VERBOSITY=10`) and attach the full output. Cause: converting <bound method BatchNormalization.call of <tensorflow.python.layers.normalization.BatchNormalization object at 0x0000026216239F28>>: AssertionError: Bad argument number for Name: 3, expecting 4
2020-12-22 18:12:41 Entity <bound method Conv.call of <tensorflow.python.layers.convolutional.Conv2D object at 0x00000262156684A8>> could not be transformed and will be executed as-is. Please report this to the AutgoGraph team. When filing the bug, set the verbosity to 10 (on Linux, `export AUTOGRAPH_VERBOSITY=10`) and attach the full output. Cause: converting <bound method Conv.call of <tensorflow.python.layers.convolutional.Conv2D object at 0x00000262156684A8>>: AssertionError: Bad argument number for Name: 3, expecting 4
2020-12-22 18:12:41 Entity <bound method BatchNormalization.call of <tensorflow.python.layers.normalization.BatchNormalization object at 0x0000026216504D68>> could not be transformed and will be executed as-is. Please report this to the AutgoGraph team. When filing the bug, set the verbosity to 10 (on Linux, `export AUTOGRAPH_VERBOSITY=10`) and attach the full output. Cause: converting <bound method BatchNormalization.call of <tensorflow.python.layers.normalization.BatchNormalization object at 0x0000026216504D68>>: AssertionError: Bad argument number for Name: 3, expecting 4
2020-12-22 18:12:41 Entity <bound method Conv.call of <tensorflow.python.layers.convolutional.Conv2D object at 0x0000026216336978>> could not be transformed and will be executed as-is. Please report this to the AutgoGraph team. When filing the bug, set the verbosity to 10 (on Linux, `export AUTOGRAPH_VERBOSITY=10`) and attach the full output. Cause: converting <bound method Conv.call of <tensorflow.python.layers.convolutional.Conv2D object at 0x0000026216336978>>: AssertionError: Bad argument number for Name: 3, expecting 4
2020-12-22 18:12:41 Entity <bound method BatchNormalization.call of <tensorflow.python.layers.normalization.BatchNormalization object at 0x00000262163547B8>> could not be transformed and will be executed as-is. Please report this to the AutgoGraph team. When filing the bug, set the verbosity to 10 (on Linux, `export AUTOGRAPH_VERBOSITY=10`) and attach the full output. Cause: converting <bound method BatchNormalization.call of <tensorflow.python.layers.normalization.BatchNormalization object at 0x00000262163547B8>>: AssertionError: Bad argument number for Name: 3, expecting 4
2020-12-22 18:12:41 Entity <bound method Conv.call of <tensorflow.python.layers.convolutional.Conv2D object at 0x0000026216474EF0>> could not be transformed and will be executed as-is. Please report this to the AutgoGraph team. When filing the bug, set the verbosity to 10 (on Linux, `export AUTOGRAPH_VERBOSITY=10`) and attach the full output. Cause: converting <bound method Conv.call of <tensorflow.python.layers.convolutional.Conv2D object at 0x0000026216474EF0>>: AssertionError: Bad argument number for Name: 3, expecting 4
2020-12-22 18:12:41 Entity <bound method BatchNormalization.call of <tensorflow.python.layers.normalization.BatchNormalization object at 0x0000026216355978>> could not be transformed and will be executed as-is. Please report this to the AutgoGraph team. When filing the bug, set the verbosity to 10 (on Linux, `export AUTOGRAPH_VERBOSITY=10`) and attach the full output. Cause: converting <bound method BatchNormalization.call of <tensorflow.python.layers.normalization.BatchNormalization object at 0x0000026216355978>>: AssertionError: Bad argument number for Name: 3, expecting 4
2020-12-22 18:12:41 Entity <bound method Conv.call of <tensorflow.python.layers.convolutional.Conv2D object at 0x0000026216606A20>> could not be transformed and will be executed as-is. Please report this to the AutgoGraph team. When filing the bug, set the verbosity to 10 (on Linux, `export AUTOGRAPH_VERBOSITY=10`) and attach the full output. Cause: converting <bound method Conv.call of <tensorflow.python.layers.convolutional.Conv2D object at 0x0000026216606A20>>: AssertionError: Bad argument number for Name: 3, expecting 4
2020-12-22 18:12:41 Entity <bound method BatchNormalization.call of <tensorflow.python.layers.normalization.BatchNormalization object at 0x00000262165BFC88>> could not be transformed and will be executed as-is. Please report this to the AutgoGraph team. When filing the bug, set the verbosity to 10 (on Linux, `export AUTOGRAPH_VERBOSITY=10`) and attach the full output. Cause: converting <bound method BatchNormalization.call of <tensorflow.python.layers.normalization.BatchNormalization object at 0x00000262165BFC88>>: AssertionError: Bad argument number for Name: 3, expecting 4
2020-12-22 18:12:41 Entity <bound method Conv.call of <tensorflow.python.layers.convolutional.Conv2D object at 0x0000026216582BA8>> could not be transformed and will be executed as-is. Please report this to the AutgoGraph team. When filing the bug, set the verbosity to 10 (on Linux, `export AUTOGRAPH_VERBOSITY=10`) and attach the full output. Cause: converting <bound method Conv.call of <tensorflow.python.layers.convolutional.Conv2D object at 0x0000026216582BA8>>: AssertionError: Bad argument number for Name: 3, expecting 4
2020-12-22 18:12:41 Entity <bound method BatchNormalization.call of <tensorflow.python.layers.normalization.BatchNormalization object at 0x00000262165BFD30>> could not be transformed and will be executed as-is. Please report this to the AutgoGraph team. When filing the bug, set the verbosity to 10 (on Linux, `export AUTOGRAPH_VERBOSITY=10`) and attach the full output. Cause: converting <bound method BatchNormalization.call of <tensorflow.python.layers.normalization.BatchNormalization object at 0x00000262165BFD30>>: AssertionError: Bad argument number for Name: 3, expecting 4
2020-12-22 18:12:41 From C:\Proyectos\pose-tensorflow-master-MODIFIED\nnet\pose_net.py:66: The name tf.variable_scope is deprecated. Please use tf.compat.v1.variable_scope instead.

2020-12-22 18:12:42 Entity <bound method Conv2DTranspose.call of <tensorflow.python.layers.convolutional.Conv2DTranspose object at 0x0000026215D52FD0>> could not be transformed and will be executed as-is. Please report this to the AutgoGraph team. When filing the bug, set the verbosity to 10 (on Linux, `export AUTOGRAPH_VERBOSITY=10`) and attach the full output. Cause: converting <bound method Conv2DTranspose.call of <tensorflow.python.layers.convolutional.Conv2DTranspose object at 0x0000026215D52FD0>>: AttributeError: module 'gast' has no attribute 'Num'
2020-12-22 18:12:42 Entity <bound method Conv2DTranspose.call of <tensorflow.python.layers.convolutional.Conv2DTranspose object at 0x000002621659EA20>> could not be transformed and will be executed as-is. Please report this to the AutgoGraph team. When filing the bug, set the verbosity to 10 (on Linux, `export AUTOGRAPH_VERBOSITY=10`) and attach the full output. Cause: converting <bound method Conv2DTranspose.call of <tensorflow.python.layers.convolutional.Conv2DTranspose object at 0x000002621659EA20>>: AttributeError: module 'gast' has no attribute 'Num'
2020-12-22 18:12:42 From C:\Proyectos\pose-tensorflow-master-MODIFIED\nnet\pose_net.py:107: The name tf.losses.sigmoid_cross_entropy is deprecated. Please use tf.compat.v1.losses.sigmoid_cross_entropy instead.

2020-12-22 18:12:42 From C:\Users\Pipita\AppData\Roaming\Python\Python36\site-packages\tensorflow\python\ops\nn_impl.py:180: add_dispatch_support.<locals>.wrapper (from tensorflow.python.ops.array_ops) is deprecated and will be removed in a future version.
Instructions for updating:
Use tf.where in 2.0, which has the same broadcast rule as np.where
2020-12-22 18:12:42 From C:\Proyectos\pose-tensorflow-master-MODIFIED\nnet\losses.py:31: to_float (from tensorflow.python.ops.math_ops) is deprecated and will be removed in a future version.
Instructions for updating:
Use `tf.cast` instead.
2020-12-22 18:12:42 From C:\Proyectos\pose-tensorflow-master-MODIFIED\nnet\losses.py:38: The name tf.losses.compute_weighted_loss is deprecated. Please use tf.compat.v1.losses.compute_weighted_loss instead.

2020-12-22 18:12:42 From train.py:108: The name tf.summary.scalar is deprecated. Please use tf.compat.v1.summary.scalar instead.

2020-12-22 18:12:42 From train.py:109: The name tf.summary.merge_all is deprecated. Please use tf.compat.v1.summary.merge_all instead.

2020-12-22 18:12:42 From train.py:112: The name tf.train.Saver is deprecated. Please use tf.compat.v1.train.Saver instead.

2020-12-22 18:12:42 From train.py:115: The name tf.Session is deprecated. Please use tf.compat.v1.Session instead.

2020-12-22 18:12:42 From train.py:120: The name tf.summary.FileWriter is deprecated. Please use tf.compat.v1.summary.FileWriter instead.

2020-12-22 18:12:43 From train.py:82: The name tf.train.MomentumOptimizer is deprecated. Please use tf.compat.v1.train.MomentumOptimizer instead.

2020-12-22 18:12:47 From train.py:124: The name tf.global_variables_initializer is deprecated. Please use tf.compat.v1.global_variables_initializer instead.

2020-12-22 18:12:49 From C:\Users\Pipita\AppData\Roaming\Python\Python36\site-packages\tensorflow\python\training\saver.py:1276: checkpoint_exists (from tensorflow.python.training.checkpoint_management) is deprecated and will be removed in a future version.
Instructions for updating:
Use standard file APIs to check for files with this prefix.
2020-12-22 18:12:49 Restoring parameters from ./pretrained/resnet_v1_50.ckpt
2020-12-22 18:12:52 iteration: 0 loss: 0.0172 lr: 0.005
2020-12-22 18:12:56 From train.py:166: build_tensor_info (from tensorflow.python.saved_model.utils_impl) is deprecated and will be removed in a future version.
Instructions for updating:
This function will only be available through the v1 compatibility library as tf.compat.v1.saved_model.utils.build_tensor_info or tf.compat.v1.saved_model.build_tensor_info.
2020-12-22 18:12:57 From C:\Users\Pipita\AppData\Roaming\Python\Python36\site-packages\tensorflow\lite\python\util.py:238: convert_variables_to_constants (from tensorflow.python.framework.graph_util_impl) is deprecated and will be removed in a future version.
Instructions for updating:
Use `tf.compat.v1.graph_util.convert_variables_to_constants`
2020-12-22 18:12:57 From C:\Users\Pipita\AppData\Roaming\Python\Python36\site-packages\tensorflow\python\framework\graph_util_impl.py:270: extract_sub_graph (from tensorflow.python.framework.graph_util_impl) is deprecated and will be removed in a future version.
Instructions for updating:
Use `tf.compat.v1.graph_util.extract_sub_graph`
2020-12-22 18:12:57 Froze 269 variables.
2020-12-22 18:12:57 Converted 269 variables to const ops.
2020-12-22 18:12:57 From train.py:252: The name tf.train.write_graph is deprecated. Please use tf.io.write_graph instead.

2020-12-22 18:13:03 Froze 269 variables.
2020-12-22 18:13:03 Converted 269 variables to const ops.
2020-12-22 18:13:08 Froze 269 variables.
2020-12-22 18:13:09 Converted 269 variables to const ops.
2020-12-22 18:13:14 Froze 269 variables.
2020-12-22 18:13:14 Converted 269 variables to const ops.
2020-12-22 18:13:19 Froze 269 variables.
2020-12-22 18:13:20 Converted 269 variables to const ops.
